Workbook
Name analysis_period: 'Assumptions & Parameters'!$J$20
Name bidirectional_inverter_efficiency: 'Assumptions & Parameters'!$J$25
Name bidirectional_transformer_efficiency: 'Assumptions & Parameters'!$J$28
Name cost_of_equity_nominal: 'Assumptions & Parameters'!$J$11
Name cost_of_equity_real: 'Assumptions & Parameters'!$J$12
Name CRF_real: 'LCOS Calculator'!$G$167
Name debt_fraction: 'Assumptions & Parameters'!$J$13
Name electricity_cost: 'Assumptions & Parameters'!$J$19
Name inflation_rate: 'Assumptions & Parameters'!$J$8
Name insurance: 'Assumptions & Parameters'!$J$16
Name interest_rate_nominal: 'Assumptions & Parameters'!$J$9
Name interest_rate_real: 'Assumptions & Parameters'!$J$10
Name ITC: 'LCOS Calculator'!$G$163
Name property_tax: 'Assumptions & Parameters'!$J$15
Name PVD: 'LCOS Calculator'!$G$164
Name rectifier_efficiency: 'Assumptions & Parameters'!$J$27
Name tax_rate: 'Assumptions & Parameters'!$J$14
Name unidirectional_inverter_efficiency: 'Assumptions & Parameters'!$J$26
Name WACC_nominal: 'Assumptions & Parameters'!$J$17
Name WACC_real: 'Assumptions & Parameters'!$J$18

Sheet Introduction
C5: Energy Storage Grand Challenge (ESGC)
C6: Cost and Performance Assessment LCOS Workbook v.2024
C9: LCOS estimates the average revenue per kilowatt-hour throughput that must be obtained in order to cover costs required to build and operate a storage asset over a specified time period. This workbook calculates the LCOS in real terms and is usable for a range of storage technology types and may be used to compare diverse technologies with a common metric. For the most up-to-date energy storage cost and performance metrics, please visit Pacific Northwest National Laboratory's Energy Storage Grand Challenge Energy Storage Cost and Performance Database website (https://www.pnnl.gov/ESGC-cost-performance).
C21: Contents
C22: Introduction
C23: LCOS Calculator
C24: Terms & Abbreviations
C25: Assumptions & Parameters
C30: Acknowledgement
C31: We’d like to acknowledge and thank the US Department of Energy (DOE) Office of Clean Energy Demonstration (OCED), US DOE Office of Electricity (OE), and the US DOE Office of Energy Efficiency and Renewable Energy (EERE) for their funding and support of this effort.
C35: Disclaimer
C36: This material was prepared as an account of work sponsored by an agency of the United States Government. Neither the United States Government nor the United States Department of Energy, nor the Contractor, nor any or their employees, nor any jurisdiction or organization that has cooperated in the development of these materials, makes any warranty, express or implied, or assumes any legal liability or responsibility for the accuracy, completeness, or usefulness or any information, apparatus, product, software, or process disclosed, or represents that its use would not infringe privately owned rights. Reference herein to any specific commercial product, process, or service by trade name, trademark, manufacturer, or otherwise does not necessarily constitute or imply its endorsement, recommendation, or favoring by the United States Government or any agency thereof, or Battelle Memorial Institute. The views and opinions of authors expressed herein do not necessarily state or reflect those of the United States Government or any agency thereof.

Sheet LCOS Calculator
C4: LCOS Calculator
C7: Instructions
C8: To calculate the LCOS ($/kWh), appropriate values must be provided or selected in the yellow input cells. All dollar values supplied should be provided in current year US dollar values. No adjustments for inflation should be made. Various terms are defined in the Terms & Abbreviations page.
C12: Legend
C13: Inputs
C14: Calculations
C15: Outputs
M17: LCOS ($/kWh)
C18: Technological Parameters | E18: Technology Parameter | I18: Units | J18: Value
C19: Fill in the yellow cells with the appropriate information. Depending on technology type (e.g., electrochemical vs. mechanical) some parameters such as the cycle life and rest time after charge/discharge may not apply. | E19: Storage Type (select from drop-down) | I19: N/A | J19: Other | M19: Including cost to charge and RTE losses | P19: =IF(J32="","",(G220-G175)/G202) -> 0.15677637
E20: Rated Storage Power Capacity | I20: MW | J20: 100 | M20: Including RTE losses only | P20: =IF(J32="","",(G221-G175)/G202) -> 0.12677637
E21: Rated Storage Duration | I21: hr | J21: 4
E22: =IF(OR(J19="Battery",J19="Hydrogen"), "Round Trip Efficiency (RTE) - DC", "Round Trip Efficiency (RTE)") -> Round Trip Efficiency (RTE) | I22: % | J22: 0.52
E23: Depth of Discharge (DOD) | I23: % | J23: 0.8
E24: Required rest time after charge (if applicable) | I24: hrs
E25: Required rest time after discharge (if applicable) | I25: hrs
E26: Max Cycles at Depth of Discharge (if applicable) | I26: #
E27: Calendar life | I27: years | J27: 60
E28: Project life | I28: years | J28: 60
E29: Cycle limit per year at 100% DOD (if applicable), leave blank if none | I29: # | J29: 365
C31: Overnight Capital Cost (OCC) and O&M | E31: Cost Parameter | I31: Units | J31: Value
C32: Fill in the yellow cells with the appropriate cost values for the storage system. The OCC includes all costs necessary to achieve an operational status. | E32: Overnight Capital Cost (OCC) | I32: $/kW | J32: 1221.66
E33: Fixed O&M | I33: $/kW-yr | J33: 18.72
E34: Variable O&M | I34: $/kWh-discharged
C37: Project Parameters | E37: Adders and Requirements | J37: (select response)
C38: These parameters refer to adders and additional tax credits following those outlined in the Inflation Reduction Act. See the Terms & Abbreviations Page for more information on each. | E38: Will the project meet the Prevailing Wage & Apprenticeship Requirements? | J38: No
E39: Will the project qualify for the Energy Community Adder? | J39: No
E40: Will the project qualify for the Domestic Content Adder? | J40: No
C44: Warranty Costs (if applicable)
C45: Fill in the yellow cells below as appropriate with the cost expenditure (current year US dollar values) for any applicable warranty in each year it is incurred across the entire specified project life in cell J28.
D47: Year
D48: 0 | E48: 1 | F48: 2 | G48: 3 | H48: 4 | I48: 5 | J48: 6 | K48: 7 | L48: 8 | M48: 9 | N48: 10 | O48: 11 | P48: 12 | Q48: 13 | R48: 14 | S48: 15 | T48: 16 | U48: 17 | V48: 18 | W48: 19 | X48: 20 | Y48: 21 | Z48: 22 | AA48: 23 | AB48: 24 | AC48: 25 | AD48: 26 | AE48: 27 | AF48: 28 | AG48: 29 | AH48: 30 | AI48: 31 | AJ48: 32 | AK48: 33 | AL48: 34 | AM48: 35 | AN48: 36 | AO48: 37 | AP48: 38 | AQ48: 39 | AR48: 40 | AS48: 41 | AT48: 42 | AU48: 43 | AV48: 44 | AW48: 45 | AX48: 46 | AY48: 47 | AZ48: 48 | BA48: 49 | BB48: 50 | BC48: 51 | BD48: 52 | BE48: 53 | BF48: 54 | BG48: 55 | BH48: 56 | BI48: 57 | BJ48: 58 | BK48: 59 | BL48: 60
C50: Present Value | E50: =(SUM(E49)/((1+WACC_real)^(E48))) -> 0 | F50: =(SUM(F49)/((1+WACC_real)^(F48))) -> 0 | G50: =(SUM(G49)/((1+WACC_real)^(G48))) -> 0 | H50: =(SUM(H49)/((1+WACC_real)^(H48))) -> 0 | I50: =(SUM(I49)/((1+WACC_real)^(I48))) -> 0 | J50: =(SUM(J49)/((1+WACC_real)^(J48))) -> 0 | K50: =(SUM(K49)/((1+WACC_real)^(K48))) -> 0 | L50: =(SUM(L49)/((1+WACC_real)^(L48))) -> 0 | ... BL50: =(SUM(BL49)/((1+WACC_real)^(BL48))) -> 0
C52: Net Present Value ($) | D52: =SUM(D50:BL50) -> 0
C55: Augmentations, Replacements, Major Overhauls (ARMO) (if applicable)
C56: Various storage components may need to be replaced or augmented at different stages to maintain operation at the specified DOD across the project life. This can include items such as replacement of power equipment or augmentation of the storage block. Fill in the yellow cells below as appropriate with the cost expenditure (current year $) for each replacement, augmentation, or major overhaul in each year it is incurred across the entire specified project life in cell J28. All ARMO should be included such that the storage system can maintain the DOD specified in cell J23 for the entire project life. The cells below use adaptive highlighting to indicate which years to fill in for the indicated project life.
D60: =IF(J26="","","Suggested storage block replacement timestep (yrs) if not augmenting:") | G60: =IF(OR(J26="",J19<>"Battery"),"",MIN(J27,ROUND(J26/I105,0)))
D62: Year
C63: Component(s) | D63: 0 | E63: 1 | F63: 2 | G63: 3 | H63: 4 | I63: 5 | J63: 6 | K63: 7 | L63: 8 | M63: 9 | N63: 10 | O63: 11 | P63: 12 | Q63: 13 | R63: 14 | S63: 15 | T63: 16 | U63: 17 | V63: 18 | W63: 19 | X63: 20 | Y63: 21 | Z63: 22 | AA63: 23 | AB63: 24 | AC63: 25 | AD63: 26 | AE63: 27 | AF63: 28 | AG63: 29 | AH63: 30 | AI63: 31 | AJ63: 32 | AK63: 33 | AL63: 34 | AM63: 35 | AN63: 36 | AO63: 37 | AP63: 38 | AQ63: 39 | AR63: 40 | AS63: 41 | AT63: 42 | AU63: 43 | AV63: 44 | AW63: 45 | AX63: 46 | AY63: 47 | AZ63: 48 | BA63: 49 | BB63: 50 | BC63: 51 | BD63: 52 | BE63: 53 | BF63: 54 | BG63: 55 | BH63: 56 | BI63: 57 | BJ63: 58 | BK63: 59 | BL63: 60
C72: Present Value | E72: =(SUM(E64:E71)/((1+WACC_real)^(E63))) -> 0 | F72: =IF(F63=" "," ",SUM('LCOS Calculator'!F64:F71)/((1+WACC_real)^('LCOS Calculator'!F63))) -> 0 | G72: =IF(G63=" "," ",SUM('LCOS Calculator'!G64:G71)/((1+WACC_real)^('LCOS Calculator'!G63))) -> 0 | H72: =IF(H63=" "," ",SUM('LCOS Calculator'!H64:H71)/((1+WACC_real)^('LCOS Calculator'!H63))) -> 0 | I72: =IF(I63=" "," ",SUM('LCOS Calculator'!I64:I71)/((1+WACC_real)^('LCOS Calculator'!I63))) -> 0 | J72: =IF(J63=" "," ",SUM('LCOS Calculator'!J64:J71)/((1+WACC_real)^('LCOS Calculator'!J63))) -> 0 | K72: =IF(K63=" "," ",SUM('LCOS Calculator'!K64:K71)/((1+WACC_real)^('LCOS Calculator'!K63))) -> 0 | L72: =IF(L63=" "," ",SUM('LCOS Calculator'!L64:L71)/((1+WACC_real)^('LCOS Calculator'!L63))) -> 0 | M72: =IF(M63=" "," ",SUM('LCOS Calculator'!M64:M71)/((1+WACC_real)^('LCOS Calculator'!M63))) -> 0 | ... BL72: =IF(BL63=" "," ",SUM('LCOS Calculator'!BL64:BL71)/((1+WACC_real)^('LCOS Calculator'!BL63))) -> 0
...

Sheet Terms & Abbreviations
C4: Terms & Abbreviations
C5: Abbreviation | D5: Term | E5: Description
C6: AEO | D6: Annual energy output | E6: kilowatt-hours per year that the storage system discharges. Assumed to remain constant per year given augmentation, major overhauls, and replacements.
C7: ARMO | D7: Augmentations, replacements, & major overhauls | E7: Significant capital expenditures necessary to continue operation of the storage system at the specified depth of discharge across its project life.
C8: ARR | D8: Annualized revenue requirements | E8: The annual revenue that must be realized over the analysis period in order cover all costs associated with the project.
D9: Calendar life | E9: The maximum number of years after which the component (e.g., storage block) reaches end of life regardless of operating conditions.
C10: COE | D10: Cost of equity | E10: Rate of return paid on assets financed with equity.
C11: CRF | D11: Capital recovery factor | E11: CRF represents the constant annual payment necessary to amortize a loan over a specified time period
C12: CT | D12: Charge time | E12: Time, in hours, required to charge the storage system.
D13: Cycle life | E13: The total number of cycles that a storage system can provide before reaching end of life as a function of DOD
D14: Decommissioning Costs | E14: Costs associated with the disconnection, disassembly, removal, and site remediation. These costs may vary widely based on whether the ESS is in the built environment or outside the built environment, how far materials must be transported, and whether site remediation is necessary.
C15: DF | D15: Debt fraction | E15: The portion of capital financed with debt
C16: DOD | D16: Depth of discharge | E16: The energy discharged as a percentage of the rated energy capacity of the storage system.
D17: Domestic content adder | E17: Under the Inflation Reduction Act, energy storage may receive an ITC adder on top of their base ITC credit if they meet specific domestic content adder requirements related to the use of products produced in the US. The value of the domestic content adder is dependent on the following factors: projects receive a 10% ITC adder if they 1) meet domestic content adder requirements and 2) are either <1 MW or >1 MW but also meet the prevailing wage and apprenticeship requirements. Projects that are >1 MW but do not meet the prevailing wage & apprenticeship requirements can only achieve a 2% adder. For a complete description of domestic content adder requirements, refer to 48(a)(12) of the internal revenue code.
C18: DT | D18: Discharge time | E18: Time, in hours, required to discharge the storage system to the specified DOD.
D19: Duration | E19: The ratio of rated energy and rated power.
C20: ECC | D20: Electricity charging cost | E20: The total $/kWh cost to charge the storage system inclusive of electricity cost and costs due to RTE losses
D21: Energy community adder | E21: Under the Inflation Reduction Act energy storage may receive an ITC adder on top of their base ITC credit if they meet specific energy community adder requirements (e.g., siting on a brownfield). The value of the energy community adder is dependent on the following factors: projects receive an additional 10% ITC adder if they 1) meet the community adder requirements and 2) are either <1 MW or >1 MW but also meet the prevailing wage and apprenticeship requirements. Projects that are >1 MW but do not meet the prevailing wage & apprenticeship requirements can only achieve a 2% Energy Community Adder. For a complete description of Energy Community Adder requirements, refer to 48(a)(14) of the internal revenue code.
C22: FCR | D22: Fixed charge rate | E22: The fixed charge rate gives the percent of capital expenditures that must be recovered on an annual basis to cover annual revenue requirements accounting for depreciation, tax credits, and other components
C23: FOM | D23: Fixed operations & maintenance cost | E23: Includes all costs necessary to keep the storage system operational throughout its life that do not fluctuate based on energy throughput, such as planned maintenance, parts, and labor and benefits for staff.
C24: i | D24: Interest rate | E24: Interest rate assumed on expenditures financed with debt.
C25: ITC | D25: Investment tax credit | E25: The Inflation Reduction Act made energy storage a part of ITC which is a federal tax incentive for investments.
C26: LCOS | D26: Levelized cost of storage | E26: Gives the average revenue per unit of electricity discharged required to recover the costs of building and operating a storage asset over a specified time period
C27: N | D27: Analysis period | E27: The number of years over which capital recovery occurs.
C28: OCC | D28: Overnight capital cost | E28: Total initial capital cost incurred as if the storage system could be operational overnight
C29: p1 | D29: Property tax | E29: Property taxes as a percent of capital
C30: p2 | D30: Insurance | E30: Insurance cost as a percent of capital
C31: PL | D31: Project life | E31: The number of years a project operates for prior to decommissioning.
D32: Prevailing wage and apprenticeship requirements | E32: Under the Inflation Reduction Act, energy storage receives a base ITC credit of 30% if it is >1 MW and meets the Prevailing Wage & Apprenticeship Requirements. For a complete description of these requirements refer to the Inflation Reduction Act and Sections 48(a)(10) and 48(a)(11) of the internal revenue code.
C33: PVD | D33: Present value of depreciation | E33: The basis of assets is depreciated over time to account for exhaustion and wear and tear. This depreciation counts as an income tax deduction. The tax depreciation method used here is the Modified Accelerated Cost Recovery Schedule (MACRS).
D34: Rated energy | E34: The rated energy (kWh) of the storage system. Product of rated power (kW) and duration (hr)
D35: Rated power | E35: The rated power capacity (kW) of the energy storage system. It is also equal to the rated energy (kWh) divided by duration (hr).
C36: RR | D36: Revenue requirements | E36: The total revenue that must be realized in order to recover all costs associated with the project.
C37: RV | D37: Residual value | E37: When the analysis period (the time period over which they are expected to recover capital) is shorter than its project life (the number of years the system is capable of operating for), there is a follow-on value of net earnings after the financial life has passed which is considered to be residual value.
C38: rest_c | D38: Rest after charge | E38: Rest required after charging the storage system.
C39: rest_d | D39: Rest after discharge | E39: Rest required after discharging the storage system.
C40: RTE | D40: Round trip efficiency | E40: The ratio of energy discharged to the grid from a starting state of charge to the energy received from the grid to bring the ESS to the same starting state of charge.
C41: t | D41: Tax rate | E41: Combined federal and state tax rate
C42: VOM | D42: Variable operations & maintenance cost | E42: Includes all costs necessary to keep the storage system operational throughout its life that do fluctuate based on throughput.
D43: Warranty costs | E43: Fees to the equipment provider for manufacturability and performance assurance over designated lifespan
...

Sheet Assumptions & Parameters
C4: Assumptions & Parameters
C6: Financial Assumptions
F7: Parameter | J7: Value
F8: Inflation Rate | J8: 0.028
F9: Interest Rate - Nominal | J9: 0.08
F10: Interest Rate - Real | J10: =(1+J9)/(1+J8)-1 -> 0.050583658
F11: COE - nominal | J11: 0.13
F12: COE - real | J12: =(1+J11)/(1+J8)-1 -> 0.09922179
F13: Debt Fraction | J13: 0.5
F14: Tax Rate (Federal and State) | J14: 0.257
F15: Property Tax Rate | J15: 0.0084
F16: Insurance Rate | J16: 0.004
F17: WACC - Nominal | J17: =J13*J9*(1-J14)+(1-J13)*(J11) -> 0.09472
F18: WACC - Real | J18: =(1+J17)/(1+J8)-1 -> 0.064902724
F19: Electricity Cost ($/kWh) | J19: 0.03
F20: Analysis Period (years), N | J20: 20
F21: Fixed O&M Annual Cost Escalation Rate - Real | J21: 0.02
C23: Technological Assumptions
F24: Parameter | J24: Value
F25: Bidirectional inverter one-way efficiency | J25: 0.98
F26: Unidirectional inverter (one-way) efficiency | J26: 0.98
F27: Rectifier (one-way) efficiency | J27: 0.98
F28: Bidirectional transformer one-way efficiency | J28: 0.98
C30: Depreciation Factor (MACRS)
E32: Depreciation rate for recovery period
D33: Year | E33: 3 | F33: 5 | G33: 7 | H33: 10 | I33: 15 | J33: 20
D34: 1 | E34: 0.3333 | F34: 0.2 | G34: 0.1429 | H34: 0.1 | I34: 0.05 | J34: 0.0375
D35: 2 | E35: 0.4445 | F35: 0.32 | G35: 0.2449 | H35: 0.18 | I35: 0.095 | J35: 0.07219
D36: 3 | E36: 0.1481 | F36: 0.192 | G36: 0.1749 | H36: 0.144 | I36: 0.0855 | J36: 0.06677
D37: 4 | E37: 0.0741 | F37: 0.1152 | G37: 0.1249 | H37: 0.1152 | I37: 0.077 | J37: 0.06177
D38: 5 | F38: 0.1152 | G38: 0.0893 | H38: 0.0922 | I38: 0.0693 | J38: 0.05713
D39: 6 | F39: 0.0576 | G39: 0.0892 | H39: 0.0737 | I39: 0.0623 | J39: 0.05285
D40: 7 | G40: 0.0893 | H40: 0.0655 | I40: 0.059 | J40: 0.04888
D41: 8 | G41: 0.0446 | H41: 0.0655 | I41: 0.059 | J41: 0.04522
D42: 9 | H42: 0.0656 | I42: 0.0591 | J42: 0.04462
D43: 10 | H43: 0.0655 | I43: 0.059 | J43: 0.04461
D44: 11 | H44: 0.0328 | I44: 0.0591 | J44: 0.04462
D45: 12 | I45: 0.059 | J45: 0.04461
D46: 13 | I46: 0.0591 | J46: 0.04462
D47: 14 | I47: 0.059 | J47: 0.04461
...
